<?xml version="1.0" ?>
<!-- =================================================================================== -->
<!-- |    This document was autogenerated by xacro from g500ARM5.urdf.xacro            | -->
<!-- |    EDITING THIS FILE BY HAND IS NOT RECOMMENDED                                 | -->
<!-- =================================================================================== -->
<robot name="girona500" xmlns:xacro="http://www.ros.org/wiki/xacro">
  <link name="base_link">
    <inertial>
      <mass value="95"/>
      <inertia ixx="100" ixy="0" ixz="0" iyy="100" iyz="0" izz="100"/>
    </inertial>
    <visual>
      <origin rpy="-1.570796327 0 3.141592654" xyz="-0.2 0 0.75"/>
      <geometry>
        <mesh filename="robot/GIRONA500/g500_March11.osg"/>
      </geometry>
    </visual>
  </link>
  <link name="pan_tilt_base" />

  <joint name="pan_tilt_base_fixed" type="fixed">
  	<origin xyz="0.6 0 0" rpy="0 0 0" />
	<parent link = "base_link" />
	<child link = "pan_tilt_base" />

  </joint>
  <link name="pan_base" />
  <link name="tilt_base" />

  <joint name="pan" type="revolute" >
  	<origin xyz="0 0 0" rpy="0 0 0" />
	<parent link="pan_tilt_base" />
	<child link="pan_base" />
	<axis xyz= "0 0 1" />
	<limit lower="-1.57" upper="1.57" effort="39" velocity="1.0" />
  </joint>
  <joint name="tilt" type="revolute" >
  	<origin xyz="0 0 0" rpy="0 0 0" />
	<parent link="pan_base" />
	<child link="tilt_base" />
	<axis xyz= "0 1 0" />
	<limit lower="-1.57" upper="1.57" effort="39" velocity="1.0" />
  </joint>
</robot>

